2022-11-08 09:57:58,353 INFO    MainThread:93509 [wandb_setup.py:_flush():68] Configure stats pid to 93509
2022-11-08 09:57:58,353 INFO    MainThread:93509 [wandb_setup.py:_flush():68] Loading settings from /home/015898207/.config/wandb/settings
2022-11-08 09:57:58,353 INFO    MainThread:93509 [wandb_setup.py:_flush():68] Loading settings from /home/015898207/geometry-dex/wandb/settings
2022-11-08 09:57:58,353 INFO    MainThread:93509 [wandb_setup.py:_flush():68] Loading settings from environment variables: {'_require_service': 'True', 'api_key': '***REDACTED***', 'mode': 'offline'}
2022-11-08 09:57:58,353 INFO    MainThread:93509 [wandb_setup.py:_flush():68] Inferring run settings from compute environment: {'program': '<python with no main file>'}
2022-11-08 09:57:58,354 INFO    MainThread:93509 [wandb_init.py:_log_setup():476] Logging user logs to /home/015898207/geometry-dex/wandb/offline-run-20221108_095758-2v1x6xg6/logs/debug.log
2022-11-08 09:57:58,354 INFO    MainThread:93509 [wandb_init.py:_log_setup():477] Logging internal logs to /home/015898207/geometry-dex/wandb/offline-run-20221108_095758-2v1x6xg6/logs/debug-internal.log
2022-11-08 09:57:58,354 INFO    MainThread:93509 [wandb_init.py:init():516] calling init triggers
2022-11-08 09:57:58,354 INFO    MainThread:93509 [wandb_init.py:init():520] wandb.init called with sweep_config: {}
config: {}
2022-11-08 09:57:58,354 INFO    MainThread:93509 [wandb_init.py:init():536] re-initializing run, found existing run on stack: 1k2w778q
2022-11-08 09:57:58,356 INFO    MainThread:93509 [wandb_run.py:_finish():1746] finishing run offline-demo/1k2w778q
2022-11-08 09:57:58,357 INFO    MainThread:93509 [jupyter.py:save_history():448] not saving jupyter history
2022-11-08 09:57:58,357 INFO    MainThread:93509 [jupyter.py:save_ipynb():378] not saving jupyter notebook
2022-11-08 09:57:58,357 INFO    MainThread:93509 [wandb_init.py:_jupyter_teardown():408] cleaning up jupyter logic
2022-11-08 09:57:58,357 INFO    MainThread:93509 [wandb_run.py:_atexit_cleanup():1949] got exitcode: 0
2022-11-08 09:57:58,357 INFO    MainThread:93509 [wandb_run.py:_restore():1932] restore
2022-11-08 09:57:58,357 INFO    MainThread:93509 [wandb_run.py:_restore():1938] restore done
2022-11-08 09:58:01,399 WARNING MsgRouterThr:93509 [router.py:message_loop():77] message_loop has been closed
2022-11-08 09:58:09,362 INFO    MainThread:93509 [wandb_run.py:_restore():1932] restore
2022-11-08 09:58:09,362 INFO    MainThread:93509 [wandb_run.py:_restore():1938] restore done
2022-11-08 09:58:09,432 ERROR   MainThread:93509 [wandb_init.py:init():1105] error
Traceback (most recent call last):
  File "/home/015898207/anaconda3/envs/om/lib/python3.6/site-packages/wandb/sdk/wandb_run.py", line 1958, in _atexit_cleanup
    self._on_finish()
  File "/home/015898207/anaconda3/envs/om/lib/python3.6/site-packages/wandb/sdk/wandb_run.py", line 2266, in _on_finish
    _ = exit_handle.wait(timeout=-1, on_progress=self._on_progress_exit)
  File "/home/015898207/anaconda3/envs/om/lib/python3.6/site-packages/wandb/sdk/lib/mailbox.py", line 273, in wait
    on_probe(probe_handle)
  File "/home/015898207/anaconda3/envs/om/lib/python3.6/site-packages/wandb/sdk/wandb_run.py", line 2228, in _on_probe_exit
    result = handle.wait(timeout=0)
  File "/home/015898207/anaconda3/envs/om/lib/python3.6/site-packages/wandb/sdk/lib/mailbox.py", line 259, in wait
    raise MailboxError("transport failed")
wandb.errors.MailboxError: transport failed

During handling of the above exception, another exception occurred:

Traceback (most recent call last):
  File "/home/015898207/anaconda3/envs/om/lib/python3.6/site-packages/wandb/sdk/wandb_init.py", line 1078, in init
    run = wi.init()
  File "/home/015898207/anaconda3/envs/om/lib/python3.6/site-packages/wandb/sdk/wandb_init.py", line 548, in init
    self._wl._global_run_stack[-1].finish()
  File "/home/015898207/anaconda3/envs/om/lib/python3.6/site-packages/wandb/sdk/wandb_run.py", line 292, in wrapper
    return func(self, *args, **kwargs)
  File "/home/015898207/anaconda3/envs/om/lib/python3.6/site-packages/wandb/sdk/wandb_run.py", line 255, in wrapper
    return func(self, *args, **kwargs)
  File "/home/015898207/anaconda3/envs/om/lib/python3.6/site-packages/wandb/sdk/wandb_run.py", line 1739, in finish
    return self._finish(exit_code, quiet)
  File "/home/015898207/anaconda3/envs/om/lib/python3.6/site-packages/wandb/sdk/wandb_run.py", line 1752, in _finish
    self._atexit_cleanup(exit_code=exit_code)
  File "/home/015898207/anaconda3/envs/om/lib/python3.6/site-packages/wandb/sdk/wandb_run.py", line 1969, in _atexit_cleanup
    self._backend.cleanup()
  File "/home/015898207/anaconda3/envs/om/lib/python3.6/site-packages/wandb/sdk/backend/backend.py", line 252, in cleanup
    self.interface.join()
  File "/home/015898207/anaconda3/envs/om/lib/python3.6/site-packages/wandb/sdk/interface/interface_shared.py", line 573, in join
    super().join()
  File "/home/015898207/anaconda3/envs/om/lib/python3.6/site-packages/wandb/sdk/interface/interface.py", line 712, in join
    _ = self._communicate_shutdown()
  File "/home/015898207/anaconda3/envs/om/lib/python3.6/site-packages/wandb/sdk/interface/interface_shared.py", line 516, in _communicate_shutdown
    _ = self._communicate(record)
  File "/home/015898207/anaconda3/envs/om/lib/python3.6/site-packages/wandb/sdk/interface/interface_shared.py", line 255, in _communicate
    return self._communicate_async(rec, local=local).get(timeout=timeout)
  File "/home/015898207/anaconda3/envs/om/lib/python3.6/site-packages/wandb/sdk/interface/interface_sock.py", line 58, in _communicate_async
    future = self._router.send_and_receive(rec, local=local)
  File "/home/015898207/anaconda3/envs/om/lib/python3.6/site-packages/wandb/sdk/interface/router.py", line 94, in send_and_receive
    self._send_message(rec)
  File "/home/015898207/anaconda3/envs/om/lib/python3.6/site-packages/wandb/sdk/interface/router_sock.py", line 36, in _send_message
    self._sock_client.send_record_communicate(record)
  File "/home/015898207/anaconda3/envs/om/lib/python3.6/site-packages/wandb/sdk/lib/sock_client.py", line 216, in send_record_communicate
    self.send_server_request(server_req)
  File "/home/015898207/anaconda3/envs/om/lib/python3.6/site-packages/wandb/sdk/lib/sock_client.py", line 155, in send_server_request
    self._send_message(msg)
  File "/home/015898207/anaconda3/envs/om/lib/python3.6/site-packages/wandb/sdk/lib/sock_client.py", line 152, in _send_message
    self._sendall_with_error_handle(header + data)
  File "/home/015898207/anaconda3/envs/om/lib/python3.6/site-packages/wandb/sdk/lib/sock_client.py", line 130, in _sendall_with_error_handle
    sent = self._sock.send(data)
BrokenPipeError: [Errno 32] Broken pipe
